<?xml version='1.0'?>

<robot name="myrobot" xmlns:xacro="http://www.ros.org/wiki/xacro">


  <!---->

  <!--camera -->
  <xacro:property name="cameraSize" value="0.01"/>
  <xacro:property name="cameraMass" value="0.03"/>

  <!--INS -->



  <!--Payload -->




   <!--Laptop -->





  <xacro:include filename="$(find boilerbot_description_integ)/urdf/mybot.gazebo" />
  <xacro:include filename="$(find boilerbot_description_integ)/urdf/materials.xacro" />
  <xacro:include filename="$(find boilerbot_description_integ)/urdf/macros.xacro" />




  <link name="chassis">
    <pose>0 0 0 0 0</pose>
    <collision>
      <origin xyz="0 0 0" rpy="0 0 0"/>
      <geometry>
    	<box size="0.1 0.1 0.1"/>
      </geometry>
    </collision>

    <visual>
      <origin xyz="0 0 0" rpy="0 0 0"/>
      <geometry>
        <mesh filename="package://boilerbot_description_integ/meshes/bodyNoWheels.dae"/>
      </geometry>
    </visual>

    <inertial>
      <mass value="76.65" />
      <origin xyz="0 0 0" rpy="0 0 0"/>
      <inertia ixx="1" ixy="0" ixz="0" iyy="1" iyz="0" izz="1" />
    </inertial>
  </link>

<!--Left Drive Wheel -->

  <link name="left_drive_wheel">
    <collision>
      <origin xyz="0 0 0" rpy="0 0 0"/>
      <geometry>
        <mesh filename="package://boilerbot_description_integ/meshes/driveWheelLeft.dae"/>
      </geometry>
    </collision>

    <visual>
      <origin xyz="0 0 0" rpy="0 0 0"/>
      <geometry>
        <mesh filename="package://boilerbot_description_integ/meshes/driveWheelLeft.dae"/>
      </geometry>
    </visual>

    <inertial>
      <mass value="2.5" />
      <origin xyz="0 0 0" rpy="0 0 0"/>
      <inertia ixx="1" ixy="0" ixz="0" iyy="1" iyz="0" izz="1" />
    </inertial>
  </link>

  <joint type="continuous" name="left_drive_hinge">
    <origin xyz="-0.0 0.0 0" rpy="0 0 0"/>
    <child link="left_drive_wheel"/>
    <parent link="chassis"/>
    <axis xyz="0 1 0" rpy="0 0 0"/>
    <limit effort="100" velocity="100"/>
    <joint_properties damping="0.0" friction="0.0"/>
  </joint>

<!--Right Drive Wheel -->

  <link name="right_drive_wheel">
    <collision>
      <origin xyz="0 0 0" rpy="0 0 0"/>
      <geometry>
        <mesh filename="package://boilerbot_description_integ/meshes/driveWheelRight.dae"/>
      </geometry>
    </collision>

    <visual>
      <origin xyz="0 0 0" rpy="0 0 0"/>
      <geometry>
        <mesh filename="package://boilerbot_description_integ/meshes/driveWheelRight.dae"/>
      </geometry>
    </visual>

    <inertial>
      <mass value="2.5" />
      <origin xyz="0 0 0" rpy="0 0 0"/>
      <inertia ixx="1" ixy="0" ixz="0" iyy="1" iyz="0" izz="1" />
    </inertial>
  </link>

  <joint type="continuous" name="right_drive_hinge">
    <origin xyz="-0.0 0.0 0" rpy="0 0 0"/>
    <child link="right_drive_wheel"/>
    <parent link="chassis"/>
    <axis xyz="0 1 0" rpy="0 0 0"/>
    <limit effort="100" velocity="100"/>
    <joint_properties damping="0.0" friction="0.0"/>
  </joint>

<!--Left Castor Wheel -->

  <link name="left_castor_wheel">
    <collision>
      <origin xyz="0 0 0" rpy="0 0 0"/>
      <geometry>
        <mesh filename="package://boilerbot_description_integ/meshes/castorLeft.dae"/>
      </geometry>
    </collision>

    <visual>
      <origin xyz="0 0 0" rpy="0 0 0"/>
      <geometry>
        <mesh filename="package://boilerbot_description_integ/meshes/castorLeft.dae"/>
      </geometry>
    </visual>

    <inertial>
      <mass value="1.5" />
      <origin xyz="0 0 0" rpy="0 0 0"/>
      <inertia ixx="1" ixy="0" ixz="0" iyy="1" iyz="0" izz="1" />
    </inertial>
  </link>

  <joint type="continuous" name="left_castor_hinge">
    <origin xyz="0.0 0.0 0" rpy="0 0 0"/>
    <child link="left_castor_wheel"/>
    <parent link="chassis"/>
    <axis xyz="0 1 0" rpy="0 0 0"/>
    <limit effort="100" velocity="100"/>
    <joint_properties damping="0.0" friction="0.0"/>
  </joint>

<!--Right Castor Wheel -->

  <link name="right_castor_wheel">
    <collision>
      <origin xyz="0 0 0" rpy="0 0 0"/>
      <geometry>
        <mesh filename="package://boilerbot_description_integ/meshes/castorRight.dae"/>
      </geometry>
    </collision>

    <visual>
      <origin xyz="0 0 0" rpy="0 0 0"/>
      <geometry>
        <mesh filename="package://boilerbot_description_integ/meshes/castorRight.dae"/>
      </geometry>
    </visual>

    <inertial>
      <mass value="1.5" />
      <origin xyz="0 0 0" rpy="0 0 0"/>
      <inertia ixx="1" ixy="0" ixz="0" iyy="1" iyz="0" izz="1" />
    </inertial>
  </link>

  <joint type="continuous" name="right_castor_hinge">
    <origin xyz="-0.0 0.0 0" rpy="0 0 0"/>
    <child link="right_castor_wheel"/>
    <parent link="chassis"/>
    <axis xyz="0 1 0" rpy="0 0 0"/>
    <limit effort="100" velocity="100"/>
    <joint_properties damping="0.0" friction="0.0"/>
  </joint>

<!-- Camera -->

  <link name="camera">
    <collision>
      <origin xyz="0 0 0" rpy="0 0 0"/>
      <geometry>
        <box size="0.1 0.01 0.1"/>
      </geometry>
    </collision>

    <visual>
      <origin xyz="0 0 0" rpy="0 0 0"/>
      <geometry>
        <box size="${cameraSize} ${cameraSize} ${cameraSize}"/>
      </geometry>
      <material name="green"/>
    </visual>

    <inertial>
      <mass value="0.1" />
      <origin xyz="0 0 0" rpy="0 0 0"/>
      <box_inertia m="0.1" x="0.1" y="0.1" z="0.1" />
      <inertia ixx="1e-6" ixy="0" ixz="0" iyy="1e-6" iyz="0" izz="1e-6" />
    </inertial>
  </link>

  <joint name="camera_joint" type="fixed">
    <axis xyz="0 1 0" />
    <origin xyz="0 -0.06 1.046" rpy="-0 0.1 1.57"/>
    <parent link="chassis"/>
    <child link="camera"/>
  </joint>

  <!-- Hokuyo Laser -->
  <link name="hokuyo">
    <collision>
      <origin xyz="0 0 0" rpy="0 0 0"/>
      <geometry>
    	<box size="0.1 0.1 0.1"/>
      </geometry>
    </collision>

    <visual>
      <origin xyz="0 0 0" rpy="0 0 0"/>
      <geometry>
        <mesh filename="package://boilerbot_description_integ/meshes/hokuyo.dae"/>
      </geometry>
    </visual>

    <inertial>
      <mass value="1e-5" />
      <origin xyz="0 0 0" rpy="0 0 0"/>
      <inertia ixx="1e-6" ixy="0" ixz="0" iyy="1e-6" iyz="0" izz="1e-6" />
    </inertial>
  </link>

  <joint name="hokuyo_joint" type="fixed">
    <axis xyz="0 1 0" />
    <origin xyz="0 0.2612 .46" rpy="0 0.015 1.57"/>
    <parent link="chassis"/>
    <child link="hokuyo"/>
  </joint>


</robot>

